Workbook

Sheet Balance Sheet
A1: Deccan Polyfab Industries Ltd (fictional sample) - Financial Statements (Standalone)
A2: All figures INR Crore. Blue = extracted from the uploaded PDF (edit if needed); black = formulas. Source: Sample_Annual_Report_DeccanPolyfab_FY25.pdf
A4: Key | B4: Particulars | C4: FY2024 | D4: FY2025
A5: BALANCE SHEET
B6: Equity
A7: share_capital | B7: Equity Share Capital | C7: 50 | D7: 50
A8: other_equity | B8: Other Equity (Reserves & Surplus) | C8: 380 | D8: 420
A9: total_equity | B9: Total Equity (Net Worth) | C9: 430 | D9: 470
A10: minority_interest | B10: Non-controlling Interest
B11: Non-current Liabilities
A12: long_term_borrowings | B12: Long-term Borrowings | C12: 260 | D12: 380
A13: lease_liabilities_nc | B13: Lease Liabilities (Non-current) | C13: 12 | D13: 10
A14: other_nc_fin_liabilities | B14: Other Non-current Financial Liabilities
A15: long_term_provisions | B15: Long-term Provisions | C15: 7 | D15: 8
A16: deferred_tax_liabilities | B16: Deferred Tax Liabilities (Net) | C16: 20 | D16: 22
A17: other_nc_liabilities | B17: Other Non-current Liabilities
B18: Current Liabilities
A19: short_term_borrowings | B19: Short-term Borrowings | C19: 169 | D19: 300
A20: current_maturities_ltd | B20: of which: Current Maturities of LTD (memo, inside ST borrowings)
A21: lease_liabilities_c | B21: Lease Liabilities (Current)
A22: trade_payables | B22: Trade Payables | C22: 190 | D22: 210
A23: other_current_fin_liabilities | B23: Other Current Financial Liabilities | C23: 35 | D23: 40
A24: other_current_liabilities | B24: Other Current Liabilities | C24: 22 | D24: 25
A25: short_term_provisions | B25: Short-term Provisions | C25: 4 | D25: 5
A26: current_tax_liabilities | B26: Current Tax Liabilities (Net) | C26: 2 | D26: 3
A27: total_current_liabilities | B27: Total Current Liabilities | C27: 422 | D27: 583
B28: Totals
A29: total_equity_and_liabilities | B29: Total Equity & Liabilities | C29: 1151 | D29: 1473
B30: Non-current Assets
A31: ppe | B31: Property, Plant & Equipment (Net Block) | C31: 410 | D31: 420
A32: cwip | B32: Capital Work-in-Progress | C32: 90 | D32: 95
A33: right_of_use | B33: Right-of-Use Assets | C33: 14 | D33: 12
A34: investment_property | B34: Investment Property
A35: goodwill | B35: Goodwill
A36: intangibles | B36: Other Intangible Assets (incl. under development) | C36: 6 | D36: 8
A37: nc_investments | B37: Non-current Investments | C37: 70 | D37: 110
A38: nc_loans | B38: Non-current Loans & Advances | C38: 10 | D38: 85
A39: other_nc_fin_assets | B39: Other Non-current Financial Assets | C39: 9 | D39: 10
A40: deferred_tax_assets | B40: Deferred Tax Assets (Net)
A41: capital_advances | B41: Capital Advances | C41: 8 | D41: 30
...

Sheet Ratios
A1: Deccan Polyfab Industries Ltd (fictional sample) - Ratio Analysis (live formulas on 'Balance Sheet')
A2: Green = within benchmark, amber = watch, red = outside benchmark. Benchmarks are general bank norms; adjust to your policy.
A4: Category | B4: Ratio | C4: FY2024 | D4: FY2025 | E4: Good if | F4: Benchmark (good) | G4: Red line | H4: Formula / note
A5: Liquidity
B6: Current Ratio | C6: =IFERROR('Balance Sheet'!C53/'Balance Sheet'!C27,"n.a.") | D6: =IFERROR('Balance Sheet'!D53/'Balance Sheet'!D27,"n.a.") | E6: Higher | F6: 1.33 | G6: 1 | H6: Bank benchmark 1.33x | total_current_assets/total_current_liabilities
B7: Quick Ratio | C7: =IFERROR(('Balance Sheet'!C53-'Balance Sheet'!C44)/'Balance Sheet'!C27,"n.a.") | D7: =IFERROR(('Balance Sheet'!D53-'Balance Sheet'!D44)/'Balance Sheet'!D27,"n.a.") | E7: Higher | F7: 1 | G7: 0.7 | H7: (total_current_assets-inventories)/total_current_liabilities
B8: Cash Ratio | C8: =IFERROR('Balance Sheet'!C95/'Balance Sheet'!C27,"n.a.") | D8: =IFERROR('Balance Sheet'!D95/'Balance Sheet'!D27,"n.a.") | E8: Higher | F8: 0.3 | G8: 0.1 | H8: liquid_funds/total_current_liabilities
B9: Net Working Capital (Cr) | C9: =IFERROR('Balance Sheet'!C102,"n.a.") | D9: =IFERROR('Balance Sheet'!D102,"n.a.") | E9: Higher | F9: 0 | G9: -0.0001 | H9: Negative NWC = short-term funds in long-term assets | nwc
B10: MPBF - Tandon Method II (Cr) | C10: =IFERROR(0.75*'Balance Sheet'!C53-('Balance Sheet'!C27-'Balance Sheet'!C19),"n.a.") | D10: =IFERROR(0.75*'Balance Sheet'!D53-('Balance Sheet'!D27-'Balance Sheet'!D19),"n.a.") | E10: - | H10: Max permissible bank finance | 0.75*total_current_assets-(total_current_liabilities-short_term_borrowings)
A11: Leverage
B12: Debt / Equity | C12: =IFERROR('Balance Sheet'!C94/'Balance Sheet'!C9,"n.a.") | D12: =IFERROR('Balance Sheet'!D94/'Balance Sheet'!D9,"n.a.") | E12: Lower | F12: 1 | G12: 2 | H12: total_debt/total_equity
B13: TOL / TNW | C13: =IFERROR('Balance Sheet'!C100/'Balance Sheet'!C101,"n.a.") | D13: =IFERROR('Balance Sheet'!D100/'Balance Sheet'!D101,"n.a.") | E13: Lower | F13: 3 | G13: 4 | H13: Bank benchmark <= 3x | tol/tnw
B14: Total Debt / EBITDA | C14: =IFERROR('Balance Sheet'!C94/'Balance Sheet'!C98,"n.a.") | D14: =IFERROR('Balance Sheet'!D94/'Balance Sheet'!D98,"n.a.") | E14: Lower | F14: 3 | G14: 5 | H14: total_debt/ebitda
B15: Net Debt / EBITDA | C15: =IFERROR('Balance Sheet'!C96/'Balance Sheet'!C98,"n.a.") | D15: =IFERROR('Balance Sheet'!D96/'Balance Sheet'!D98,"n.a.") | E15: Lower | F15: 2.5 | G15: 4.5 | H15: net_debt/ebitda
A16: Coverage
B17: Interest Coverage (EBIT / Finance cost) | C17: =IF(ABS('Balance Sheet'!C66)=0,"n.a.",IFERROR('Balance Sheet'!C99/'Balance Sheet'!C66,"n.a.")) | D17: =IF(ABS('Balance Sheet'!D66)=0,"n.a.",IFERROR('Balance Sheet'!D99/'Balance Sheet'!D66,"n.a.")) | E17: Higher | F17: 3 | G17: 1.5 | H17: ebit/finance_cost
B18: EBITDA / Finance cost | C18: =IF(ABS('Balance Sheet'!C66)=0,"n.a.",IFERROR('Balance Sheet'!C98/'Balance Sheet'!C66,"n.a.")) | D18: =IF(ABS('Balance Sheet'!D66)=0,"n.a.",IFERROR('Balance Sheet'!D98/'Balance Sheet'!D66,"n.a.")) | E18: Higher | F18: 4 | G18: 2 | H18: ebitda/finance_cost
B19: DSCR (approx.) | C19: =IF(ABS('Balance Sheet'!C20)=0,"n.a.",IFERROR(('Balance Sheet'!C73+'Balance Sheet'!C67+'Balance Sheet'!C66)/('Balance Sheet'!C66+'Balance Sheet'!C20),"n.a.")) | D19: =IF(ABS('Balance Sheet'!D20)=0,"n.a.",IFERROR(('Balance Sheet'!D73+'Balance Sheet'!D67+'Balance Sheet'!D66)/('Balance Sheet'!D66+'Balance Sheet'!D20),"n.a.")) | E19: Higher | F19: 1.5 | G19: 1.2 | H19: (PAT+Dep+Int)/(Int+current maturities) | (pat+depreciation+finance_cost)/(finance_cost+current_maturities_ltd)
A20: Profitability
B21: EBITDA Margin | C21: =IFERROR('Balance Sheet'!C98/'Balance Sheet'!C58,"n.a.") | D21: =IFERROR('Balance Sheet'!D98/'Balance Sheet'!D58,"n.a.") | E21: Higher | F21: 0.12 | G21: 0.05 | H21: ebitda/revenue
B22: PAT Margin | C22: =IFERROR('Balance Sheet'!C73/'Balance Sheet'!C58,"n.a.") | D22: =IFERROR('Balance Sheet'!D73/'Balance Sheet'!D58,"n.a.") | E22: Higher | F22: 0.06 | G22: 0 | H22: pat/revenue
B23: Return on Equity (closing) | C23: =IFERROR('Balance Sheet'!C73/'Balance Sheet'!C9,"n.a.") | D23: =IFERROR('Balance Sheet'!D73/'Balance Sheet'!D9,"n.a.") | E23: Higher | F23: 0.15 | G23: 0.05 | H23: pat/total_equity
B24: ROCE (EBIT / (Equity + Debt)) | C24: =IFERROR('Balance Sheet'!C99/('Balance Sheet'!C9+'Balance Sheet'!C94),"n.a.") | D24: =IFERROR('Balance Sheet'!D99/('Balance Sheet'!D9+'Balance Sheet'!D94),"n.a.") | E24: Higher | F24: 0.15 | G24: 0.08 | H24: ebit/(total_equity+total_debt)
B25: Return on Assets | C25: =IFERROR('Balance Sheet'!C73/'Balance Sheet'!C55,"n.a.") | D25: =IFERROR('Balance Sheet'!D73/'Balance Sheet'!D55,"n.a.") | E25: Higher | F25: 0.06 | G25: 0.02 | H25: pat/total_assets
A26: Efficiency
B27: Asset Turnover | C27: =IFERROR('Balance Sheet'!C58/'Balance Sheet'!C55,"n.a.") | D27: =IFERROR('Balance Sheet'!D58/'Balance Sheet'!D55,"n.a.") | E27: Higher | F27: 1 | G27: 0.5 | H27: revenue/total_assets
B28: Fixed Asset Turnover | C28: =IFERROR('Balance Sheet'!C58/'Balance Sheet'!C31,"n.a.") | D28: =IFERROR('Balance Sheet'!D58/'Balance Sheet'!D31,"n.a.") | E28: Higher | F28: 2 | G28: 1 | H28: revenue/ppe
B29: Debtor Days | C29: =IFERROR('Balance Sheet'!C46/'Balance Sheet'!C58*365,"n.a.") | D29: =IFERROR('Balance Sheet'!D46/'Balance Sheet'!D58*365,"n.a.") | E29: Lower | F29: 60 | G29: 120 | H29: trade_receivables/revenue*365
B30: Inventory Days (on COGS) | C30: =IFERROR('Balance Sheet'!C44/MAX('Balance Sheet'!C97,0.0001)*365,"n.a.") | D30: =IFERROR('Balance Sheet'!D44/MAX('Balance Sheet'!D97,0.0001)*365,"n.a.") | E30: Lower | F30: 60 | G30: 120 | H30: inventories/MAX(cogs,0.0001)*365
B31: Creditor Days (on COGS) | C31: =IFERROR('Balance Sheet'!C22/MAX('Balance Sheet'!C97,0.0001)*365,"n.a.") | D31: =IFERROR('Balance Sheet'!D22/MAX('Balance Sheet'!D97,0.0001)*365,"n.a.") | E31: - | H31: Very high = stretched suppliers | trade_payables/MAX(cogs,0.0001)*365
B32: Cash Conversion Cycle | C32: =IFERROR('Balance Sheet'!C46/'Balance Sheet'!C58*365+'Balance Sheet'!C44/MAX('Balance Sheet'!C97,0.0001)*365-'Balance Sheet'!C22/MAX('Balance Sheet'!C97,0.0001)*365,"n.a.") | D32: =IFERROR('Balance Sheet'!D46/'Balance Sheet'!D58*365+'Balance Sheet'!D44/MAX('Balance Sheet'!D97,0.0001)*365-'Balance Sheet'!D22/MAX('Balance Sheet'!D97,0.0001)*365,"n.a.") | E32: Lower | F32: 60 | G32: 120 | H32: trade_receivables/revenue*365+inventories/MAX(cogs,0.0001)*365-trade_payables/MAX(cogs,0.0001)*365
A33: Cash Flow Quality
B34: CFO / EBITDA | C34: =IFERROR('Balance Sheet'!C76/'Balance Sheet'!C98,"n.a.") | D34: =IFERROR('Balance Sheet'!D76/'Balance Sheet'!D98,"n.a.") | E34: Higher | F34: 0.7 | G34: 0.4 | H34: Earnings converting to cash? | cfo/ebitda
B35: CFO / PAT | C35: =IFERROR('Balance Sheet'!C76/'Balance Sheet'!C73,"n.a.") | D35: =IFERROR('Balance Sheet'!D76/'Balance Sheet'!D73,"n.a.") | E35: Higher | F35: 1 | G35: 0.5 | H35: cfo/pat
B36: Free Cash Flow (Cr) | C36: =IFERROR('Balance Sheet'!C104,"n.a.") | D36: =IFERROR('Balance Sheet'!D104,"n.a.") | E36: Higher | F36: 0 | G36: -0.0001 | H36: fcf
A37: Earnings Quality
B38: Other Income / PBT | C38: =IFERROR('Balance Sheet'!C59/'Balance Sheet'!C71,"n.a.") | D38: =IFERROR('Balance Sheet'!D59/'Balance Sheet'!D71,"n.a.") | E38: Lower | F38: 0.15 | G38: 0.3 | H38: High = core business weak | other_income/pbt
B39: Effective Tax Rate | C39: =IFERROR('Balance Sheet'!C72/'Balance Sheet'!C71,"n.a.") | D39: =IFERROR('Balance Sheet'!D72/'Balance Sheet'!D71,"n.a.") | E39: Within band | F39: 0.18 | G39: 0.1 | H39: Statutory ~25.17% | tax_expense/pbt
A40: Forensic
B41: Implied Cost of Debt | C41: =IF(ABS('Balance Sheet'!C66)=0,"n.a.",IFERROR('Balance Sheet'!C66/'Balance Sheet'!C94,"n.a.")) | D41: =IF(ABS('Balance Sheet'!D66)=0,"n.a.",IFERROR('Balance Sheet'!D66/'Balance Sheet'!D94,"n.a.")) | E41: Within band | F41: 0.06 | G41: 0.15 | H41: Too low = hidden debt / capitalised interest | finance_cost/total_debt
...

Sheet PCAF Financed Emissions
A1: Deccan Polyfab Industries Ltd (fictional sample) - PCAF Financed Emissions (Business loans / Listed equity & bonds)
A2: Yellow cells are inputs - change them and every result recalculates. Green = linked from the Balance Sheet tab (latest year).
A4: Item | B4: Value | C4: Unit | D4: Source / note
A5: INPUTS
A6: Bank's outstanding exposure | B6: 0 | C6: INR Cr | D6: Funded outstanding as on reporting date (user input)
A7: Asset class | B7: Business loans / unlisted equity | D7: 'Listed equity & corporate bonds' uses EVIC; else equity + debt
A8: Market capitalisation (listed only) | B8: 0 | C8: INR Cr | D8: Year-end market cap (user input / exchange data)
A9: Total equity (book) | B9: ='Balance Sheet'!D9 | C9: INR Cr | D9: Linked: Balance Sheet latest year
A10: Total debt (book) | B10: ='Balance Sheet'!D94 | C10: INR Cr | D10: Linked: Balance Sheet derived Total Debt
A11: Non-controlling interest | B11: ='Balance Sheet'!D10 | C11: INR Cr | D11: Linked: Balance Sheet
A12: Revenue | B12: ='Balance Sheet'!D58 | C12: INR Cr | D12: Linked: Balance Sheet
A13: Scope 1 emissions (reported) | B13: 85000 | C13: tCO2e | D13: BRSR Principle 6 (enter 0 if not reported)
A14: Scope 2 emissions (reported) | B14: 42000 | C14: tCO2e | D14: BRSR Principle 6
A15: Scope 3 emissions (reported, optional) | B15: 0 | C15: tCO2e | D15: BRSR Core / voluntary
A16: Emissions third-party assured? | B16: No | C16: Yes/No | D16: Reasonable/limited assurance on GHG -> PCAF score 1, else 2
A17: Sector emission factor (fallback) | B17: 0 | C17: tCO2e / INR Cr revenue | D17: Used only when no reported emissions. Sector: - (ILLUSTRATIVE default - replace with approved factor)
A18: CALCULATION
A19: Attribution denominator | B19: =IF(AND(LEFT(B7,6)="Listed",B8>0),B8+B10+B11,B9+B10) | C19: INR Cr | D19: EVIC for listed; equity + debt for unlisted / business loans
A20: Attribution factor | B20: =IFERROR(MIN(1,B6/B19),0) | C20: % | D20: Outstanding / denominator (capped at 100%)
A21: Company Scope 1+2 used | B21: =IF(B13+B14>0,B13+B14,B17*B12) | C21: tCO2e | D21: Reported if available, else revenue x sector factor
A22: Financed emissions - Scope 1+2 | B22: =B20*B21 | C22: tCO2e | D22: Attribution factor x company Scope 1+2
A23: Financed emissions - Scope 3 | B23: =B20*B15 | C23: tCO2e | D23: Reported separately per PCAF
A24: PCAF data quality score | B24: =IF(B13+B14>0,IF(B16="Yes",1,2),IF(B17>0,4,"n.a.")) | C24: 1 (best) - 5 | D24: 1 verified, 2 unverified, 3 physical activity, 4 revenue-based, 5 asset-based
A25: Financed emission intensity | B25: =IFERROR(B22/B6,0) | C25: tCO2e / INR Cr lent | D25: Carbon footprint of this exposure
A26: Company economic emission intensity | B26: =IFERROR(B21/B12,0) | C26: tCO2e / INR Cr revenue | D26: Compare with sector peers
A28: Method: PCAF Global GHG Accounting & Reporting Standard, Part A (Financed Emissions), business loans & listed equity/corporate bonds.
A29: Sector factors in data/emission_factors.csv are illustrative placeholders; replace them with PCAF database or bank-approved factors before reporting.

Sheet Projections & DSCR
A1: Deccan Polyfab Industries Ltd (fictional sample) - projected financials and DSCR (₹ Cr)
A2: Yellow cells are assumptions: change them and every projection, DSCR and coverage figure recalculates.
A3: Assumption | B3: Value
A4: Base revenue (latest audited) | B4: 1350
A5: Revenue growth p.a. | B5: 0.08
A6: EBITDA margin | B6: 0.17037037
A7: Depreciation (existing assets) | B7: 38
A8: Other income p.a. | B8: 18
A9: Existing term debt | B9: 380
A10: Existing term debt - remaining years | B10: 4
A11: Interest rate on existing debt | B11: 0.089855072
A12: Working-capital borrowings | B12: 360
A13: Interest rate on working capital | B13: 0.095
A14: New term loan | B14: 40
A15: New term loan rate | B15: 0.0975
... A20: Moratorium (months) | B20: 6
A22: Projection | B22: Y+1 | C22: Y+2 | D22: Y+3 | E22: Y+4 | F22: Y+5
A23: Revenue | B23: =$B$4*(1+$B$5) | C23: =B23*(1+$B$5) | D23: =C23*(1+$B$5) | E23: =D23*(1+$B$5) | F23: =E23*(1+$B$5)
A24: EBITDA | B24: =B23*$B$6 | C24: =C23*$B$6 | D24: =D23*$B$6 | E24: =E23*$B$6 | F24: =F23*$B$6
A25: Other income | B25: =$B$8 | C25: =$B$8 | D25: =$B$8 | E25: =$B$8 | F25: =$B$8
A26: Depreciation | B26: =$B$7+$B$17 | C26: =$B$7+$B$17 | D26: =$B$7+$B$17 | E26: =$B$7+$B$17 | F26: =$B$7+$B$17
A27: Existing TL - opening | B27: =$B$9 | C27: =B29 | D27: =C29 | E27: =D29 | F27: =E29
A28: Existing TL - repayment | B28: =MIN($B$9/MAX($B$10,1),B27) | C28: =MIN($B$9/MAX($B$10,1),C27) | D28: =MIN($B$9/MAX($B$10,1),D27) | E28: =MIN($B$9/MAX($B$10,1),E27) | F28: =MIN($B$9/MAX($B$10,1),F27)
A29: Existing TL - closing | B29: =B27-B28 | C29: =C27-C28 | D29: =D27-D28 | E29: =E27-E28 | F29: =F27-F28
A30: Existing TL - interest | B30: =(B27-B28/2)*$B$11 | C30: =(C27-C28/2)*$B$11 | D30: =(D27-D28/2)*$B$11 | E30: =(E27-E28/2)*$B$11 | F30: =(F27-F28/2)*$B$11
A31: New TL - interest | B31: =SUMIF('Repayment Schedule'!$B:$B,1,'Repayment Schedule'!$E:$E) | C31: =SUMIF('Repayment Schedule'!$B:$B,2,'Repayment Schedule'!$E:$E) | D31: =SUMIF('Repayment Schedule'!$B:$B,3,'Repayment Schedule'!$E:$E) | E31: =SUMIF('Repayment Schedule'!$B:$B,4,'Repayment Schedule'!$E:$E) | F31: =SUMIF('Repayment Schedule'!$B:$B,5,'Repayment Schedule'!$E:$E)
A32: New TL - repayment | B32: =SUMIF('Repayment Schedule'!$B:$B,1,'Repayment Schedule'!$F:$F) | C32: =SUMIF('Repayment Schedule'!$B:$B,2,'Repayment Schedule'!$F:$F) | D32: =SUMIF('Repayment Schedule'!$B:$B,3,'Repayment Schedule'!$F:$F) | E32: =SUMIF('Repayment Schedule'!$B:$B,4,'Repayment Schedule'!$F:$F) | F32: =SUMIF('Repayment Schedule'!$B:$B,5,'Repayment Schedule'!$F:$F)
A33: Working-capital interest | B33: =$B$12*$B$13 | C33: =$B$12*$B$13 | D33: =$B$12*$B$13 | E33: =$B$12*$B$13 | F33: =$B$12*$B$13
A34: Total interest | B34: =B30+B31+B33 | C34: =C30+C31+C33 | D34: =D30+D31+D33 | E34: =E30+E31+E33 | F34: =F30+F31+F33
A35: Profit before tax | B35: =B24+B25-B26-B34 | C35: =C24+C25-C26-C34 | D35: =D24+D25-D26-D34 | E35: =E24+E25-E26-E34 | F35: =F24+F25-F26-F34
A36: Tax | B36: =MAX(B35,0)*$B$16 | C36: =MAX(C35,0)*$B$16 | D36: =MAX(D35,0)*$B$16 | E36: =MAX(E35,0)*$B$16 | F36: =MAX(F35,0)*$B$16
A37: Profit after tax | B37: =B35-B36 | C37: =C35-C36 | D37: =D35-D36 | E37: =E35-E36 | F37: =F35-F36
A38: Cash accruals (PAT + dep.) | B38: =B37+B26 | C38: =C37+C26 | D38: =D37+D26 | E38: =E37+E26 | F38: =F37+F26
A39: Term-debt interest | B39: =B30+B31 | C39: =C30+C31 | D39: =D30+D31 | E39: =E30+E31 | F39: =F30+F31
A40: Term-debt principal | B40: =B28+B32 | C40: =C28+C32 | D40: =D28+D32 | E40: =E28+E32 | F40: =F28+F32
A41: DSCR | B41: =IFERROR((B37+B26+B39)/(B39+B40),"-") | C41: =IFERROR((C37+C26+C39)/(C39+C40),"-") | D41: =IFERROR((D37+D26+D39)/(D39+D40),"-") | E41: =IFERROR((E37+E26+E39)/(E39+E40),"-") | F41: =IFERROR((F37+F26+F39)/(F39+F40),"-")
A42: Interest coverage | B42: =IFERROR((B24+B25-B26)/B34,"-") | C42: =IFERROR((C24+C25-C26)/C34,"-") | D42: =IFERROR((D24+D25-D26)/D34,"-") | E42: =IFERROR((E24+E25-E26)/E34,"-") | F42: =IFERROR((F24+F25-F26)/F34,"-")
A43: Surplus after term repayment | B43: =B38-B40 | C43: =C38-C40 | D43: =D38-D40 | E43: =E38-E40 | F43: =F38-F40
A44: Net worth (closing) | B44: =$B$18+B37 | C44: =B44+C37 | D44: =C44+D37 | E44: =D44+E37 | F44: =E44+F37
A46: Average DSCR (total cash available / total debt service) | B46: =IFERROR((SUM(B37:F37)+SUM(B26:F26)+SUM(B39:F39))/(SUM(B39:F39)+SUM(B40:F40)),"-")
...

Sheet Repayment Schedule
A1: New term loan - quarterly repayment schedule (₹ Cr)
A2: Amount, rate, tenor and moratorium link to the assumptions on 'Projections & DSCR'.
A3: Quarter | B3: Year | C3: Opening | D3: Instalment due | E3: Interest | F3: Principal | G3: Closing | I3: Instalment | J3: =IFERROR('Projections & DSCR'!$B$14/('Projections & DSCR'!$B$19*4-ROUND('Projections & DSCR'!$B$20/3,0)),0)
A4: 1 | B4: =ROUNDUP(A4/4,0) | C4: ='Projections & DSCR'!$B$14 | D4: =IF(A4>ROUND('Projections & DSCR'!$B$20/3,0),$J$3,0) | E4: =C4*'Projections & DSCR'!$B$15/4 | F4: =MIN(D4,C4) | G4: =C4-F4
A5: 2 | B5: =ROUNDUP(A5/4,0) | C5: =G4 | D5: =IF(A5>ROUND('Projections & DSCR'!$B$20/3,0),$J$3,0) | E5: =C5*'Projections & DSCR'!$B$15/4 | F5: =MIN(D5,C5) | G5: =C5-F5
A6: 3 | B6: =ROUNDUP(A6/4,0) | C6: =G5 | D6: =IF(A6>ROUND('Projections & DSCR'!$B$20/3,0),$J$3,0) | E6: =C6*'Projections & DSCR'!$B$15/4 | F6: =MIN(D6,C6) | G6: =C6-F6
A7: 4 | B7: =ROUNDUP(A7/4,0) | C7: =G6 | D7: =IF(A7>ROUND('Projections & DSCR'!$B$20/3,0),$J$3,0) | E7: =C7*'Projections & DSCR'!$B$15/4 | F7: =MIN(D7,C7) | G7: =C7-F7
A8: 5 | B8: =ROUNDUP(A8/4,0) | C8: =G7 | D8: =IF(A8>ROUND('Projections & DSCR'!$B$20/3,0),$J$3,0) | E8: =C8*'Projections & DSCR'!$B$15/4 | F8: =MIN(D8,C8) | G8: =C8-F8
A9: 6 | B9: =ROUNDUP(A9/4,0) | C9: =G8 | D9: =IF(A9>ROUND('Projections & DSCR'!$B$20/3,0),$J$3,0) | E9: =C9*'Projections & DSCR'!$B$15/4 | F9: =MIN(D9,C9) | G9: =C9-F9
A10: 7 | B10: =ROUNDUP(A10/4,0) | C10: =G9 | D10: =IF(A10>ROUND('Projections & DSCR'!$B$20/3,0),$J$3,0) | E10: =C10*'Projections & DSCR'!$B$15/4 | F10: =MIN(D10,C10) | G10: =C10-F10
A11: 8 | B11: =ROUNDUP(A11/4,0) | C11: =G10 | D11: =IF(A11>ROUND('Projections & DSCR'!$B$20/3,0),$J$3,0) | E11: =C11*'Projections & DSCR'!$B$15/4 | F11: =MIN(D11,C11) | G11: =C11-F11
A12: 9 | B12: =ROUNDUP(A12/4,0) | C12: =G11 | D12: =IF(A12>ROUND('Projections & DSCR'!$B$20/3,0),$J$3,0) | E12: =C12*'Projections & DSCR'!$B$15/4 | F12: =MIN(D12,C12) | G12: =C12-F12
A13: 10 | B13: =ROUNDUP(A13/4,0) | C13: =G12 | D13: =IF(A13>ROUND('Projections & DSCR'!$B$20/3,0),$J$3,0) | E13: =C13*'Projections & DSCR'!$B$15/4 | F13: =MIN(D13,C13) | G13: =C13-F13
A14: 11 | B14: =ROUNDUP(A14/4,0) | C14: =G13 | D14: =IF(A14>ROUND('Projections & DSCR'!$B$20/3,0),$J$3,0) | E14: =C14*'Projections & DSCR'!$B$15/4 | F14: =MIN(D14,C14) | G14: =C14-F14
A15: 12 | B15: =ROUNDUP(A15/4,0) | C15: =G14 | D15: =IF(A15>ROUND('Projections & DSCR'!$B$20/3,0),$J$3,0) | E15: =C15*'Projections & DSCR'!$B$15/4 | F15: =MIN(D15,C15) | G15: =C15-F15
A16: 13 | B16: =ROUNDUP(A16/4,0) | C16: =G15 | D16: =IF(A16>ROUND('Projections & DSCR'!$B$20/3,0),$J$3,0) | E16: =C16*'Projections & DSCR'!$B$15/4 | F16: =MIN(D16,C16) | G16: =C16-F16
... A23: 20 | B23: =ROUNDUP(A23/4,0) | C23: =G22 | D23: =IF(A23>ROUND('Projections & DSCR'!$B$20/3,0),$J$3,0) | E23: =C23*'Projections & DSCR'!$B$15/4 | F23: =MIN(D23,C23) | G23: =C23-F23

Sheet Scenarios
A1: Scenario analysis over the projection period
A2: Each scenario flexes growth, EBITDA margin and interest rates together.
A3: Scenario | B3: Growth | C3: Margin shift | D3: Rate shift | E3: Avg DSCR | F3: Min DSCR | G3: Y+1 ICR | H3: Cum. surplus ₹ Cr
A4: Base case | B4: 0.08 | C4: 0 | D4: 0 | E4: 2.207649 | F4: 1.4479152 | G4: 3.3037583 | H4: 603.2235
A5: Upside | B5: 0.13 | C5: 0.01 | D5: 0 | E5: 2.6957498 | F5: 1.5982584 | G5: 3.6976622 | H5: 847.031
A6: Downside | B6: -0.02 | C6: -0.02 | D6: 0.01 | E6: 1.4090217 | F6: 1.1253557 | G6: 2.3250285 | H6: 207.88625
A7: Severe stress | B7: -0.1 | C7: -0.04 | D7: 0.02 | E7: 0.91898333 | F7: 0.73292028 | G7: 1.6278767 | H7: -41.885811
A9: Break-even: maximum uniform fall in projected EBITDA with minimum DSCR >= 1.00x | F9: 0.32089677

Sheet WC Assessment & DP
A1: Working-capital assessment (₹ Cr)
A2: Projected turnover ₹1,458.00 Cr; growth 8.0%.
A3: Particulars | B3: Tandon Method I | C3: Tandon Method II | D3: Turnover method
A4: Total current assets (A) | B4: 688 | C4: 688 | D4: -
A5: Other current liabilities excl. bank borrowings (B) | B5: 283 | C5: 283 | D5: -
A6: Working-capital gap (A - B) | B6: 405 | C6: 405 | D6: 364.5
A7: Minimum borrower margin | B7: 101.25 | C7: 172 | D7: 72.9
A8: Maximum permissible bank finance | B8: 303.75 | C8: 233 | D8: 291.6
A9: Requested / existing WC limit | C9: 60
A10: Assessed eligibility | C10: 233
A11: Headroom / (excess) | C11: 173
A14: Drawing power | B14: ₹ Cr
A15: Inventory | B15: 210
A16: Less: trade creditors (unpaid stock) | B16: 210
A17: Paid stock | B17: 0
A18: Less: margin 25% | B18: 0
A19: DP on stock (a) | B19: 0
A20: Trade receivables | B20: 290
A21: Eligible receivables (< 90 days, assumed 85%) | B21: 246.5
A22: Less: margin 40% | B22: 98.6
A23: DP on receivables (b) | B23: 147.9
A24: Drawing power (a + b) | B24: 147.9
A25: Sanctioned / proposed CC limit | B25: 60
A26: Available DP = lower of DP and limit | B26: 60

Sheet Security & Pricing
A1: Security cover and risk-based pricing
A2: PD scale, haircuts, cost of funds and capital ratio are illustrative - replace with the bank's policy.
A3: Security | B3: ₹ Cr
A4: Current assets (stock + receivables) - primary for CC | B4: 500
A5: Net fixed assets incl. CWIP - primary for TL | B5: 515
A6: Collateral (Immovable property) - market value | B6: 80
A7: Total security available | B7: 1095
A8: Proposed exposure (fund + non-fund) | B8: 110
A9: Total debt incl. existing lenders (security shared pari-passu) | B9: 800
A10: Security cover (x) | B10: 1.36875
A11: Fixed-asset coverage ratio (x) | B11: 1.3214286
A13: Pricing component | B13: Value
A14: Internal grade | B14: CI-5
A15: Probability of default (1-yr, illustrative master scale) | B15: 5.00%
A16: Exposure at default (non-fund at CCF 50%) | B16: ₹105.00 Cr
A17: Realisable security (after 40% haircut) | B17: ₹131.74 Cr
A18: Loss given default | B18: 10.0%
A19: Expected loss (PD x LGD x EAD) | B19: ₹0.525 Cr (0.50% p.a.)
A20: Capital required (11.5% x RW 100%) | B20: ₹12.08 Cr
A21: Cost of funds + operating cost | B21: 7.25%
A22: Cost of capital charge | B22: 0.98%
A23: Risk-based hurdle rate | B23: 8.73%
A24: Minimum price (not below benchmark) | B24: 9.00% (benchmark 9.00% + 0 bp)
... A26: RAROC at proposed rate | B26: 21.7% (target 15%)

Sheet RBI EWS & Regulatory
A1: RBI early-warning signals - 6 triggered
A2: Multiple EWS triggered - the RBI framework requires the account to be examined for Red-Flagging (RFA) and a decision within the prescribed timeline; consider a forensic audit before any fresh exposure.
A3: Early-warning signal | B3: Status | C3: Basis
A4: Default in undisputed statutory dues / delay in payment to lenders | B4: Triggered | C4: CARO: delay in statutory dues
A5: Diversion of funds / end-use not established | B5: Triggered | C5: Borrowed funds not visibly deployed in business (end-use gap); Sharp rise in loans & advances given
A6: Substantial related-party transactions / funds to group entities | B6: Not observed | C6: No indication in the financial statements
A7: Receivables disproportionate to sales / stretched debtors | B7: Triggered | C7: Receivables growing much faster than revenue
A8: Inventory build-up / stock not commensurate with turnover | B8: Not observed | C8: No indication in the financial statements
A9: Frequent change in project scope / delay in implementation (CWIP) | B9: Not observed | C9: No indication in the financial statements
A10: Critical remarks by statutory auditor / qualification / CARO | B10: Triggered | C10: Emphasis of matter in audit report; CARO: short-term funds used for long-term purposes; CARO: loans without repayment terms
A11: Large contingent or off-balance-sheet liabilities | B11: Triggered | C11: Corporate guarantees given
A12: Cash-rich yet borrowing / low yield on liquid funds (possible fictitious cash) | B12: Not observed | C12: No indication in the financial statements
A13: Manipulation indicators (Beneish / accrual-heavy profits) | B13: Triggered | C13: Revenue up but operating cash flow down; Beneish M-score indicates possible earnings manipulation
A14: High promoter pledge / reduction in promoter stake | B14: Bank data needed | C14: Shareholding pattern / NSDL data
... A30: Minimum promoter margin on working capital | B30: 1.18x current ratio | C30: Below 1.25x - check margin compliance

Sheet CMA Analysis
A1: CMA-format analysis (audited years)
A2: Forms II (operating statement), III (balance sheet analysis), IV (holding levels) and VI (fund flow).
A3: FORM II - Operating statement
A4: Particulars (₹ Cr) | B4: FY2024 | C4: FY2025
A5: Net sales (revenue from operations) | B5: 1250 | C5: 1350
A6: % rise / (fall) in net sales | B6: - | C6: 0.08
A7: Cost of sales (materials + traded goods + change in stock) | B7: 785 | C7: 840
A8: Employee cost | B8: 88 | C8: 95
A9: Other operating expenses | B9: 170 | C9: 185
A10: Operating profit before interest & depreciation (EBITDA) | B10: 207 | C10: 230
A11: Depreciation | B11: 36 | C11: 38
A12: Interest | B12: 45 | C12: 62
A13: Other income | B13: 12 | C13: 18
A14: Exceptional items | B14: 0 | C14: 0
A15: Profit before tax | B15: 138 | C15: 148
A16: Provision for tax | B16: 35 | C16: 37
A17: Net profit | B17: 103 | C17: 111
A18: PBT / net sales | B18: 0.1104 | C18: 0.10962963
A20: FORM III - Analysis of balance sheet
A21: Particulars (₹ Cr) | B21: FY2024 | C21: FY2025
A22: Short-term bank borrowings (incl. current maturities) | B22: 169 | C22: 300
A23: Trade payables | B23: 190 | C23: 210
A24: Other current liabilities & provisions | B24: 63 | C24: 73
A25: Total current liabilities | B25: 422 | C25: 583
A26: Term liabilities (long-term borrowings + leases) | B26: 272 | C26: 390
A27: Other non-current liabilities & provisions | B27: 27 | C27: 30
A28: Total outside liabilities | B28: 721 | C28: 1003
A29: Net worth | B29: 430 | C29: 470
A30: Total current assets | B30: 522 | C30: 688
A31: Net fixed assets (incl. CWIP) | B31: 514 | C31: 527
A32: Intangibles | B32: 6 | C32: 8
A33: Other non-current assets & investments | B33: 109 | C33: 250
... A38: TOL / TNW | B38: 1.7004717 | C38: 2.1709957
A40: FORM IV - Current assets and holding levels
A41: Particulars (₹ Cr) | B41: FY2024 | C41: FY2025
A42: Raw material + stock holding (days of cost of sales) | B42: 83.694268 | C42: 91.25
A43: Receivables (days of sales) | B43: 58.4 | C43: 78.407407
A44: Trade payables (days of purchases) | B44: 88.343949 | C44: 91.25
A45: Inventory | B45: 180 | C45: 210
A46: Receivables | B46: 200 | C46: 290
...
